<?xml version="1.0"?>
<robot name="roar_bot" xmlns:xacro="http://ros.org/wiki/xacro">

<!-- Define robot constants -->
<xacro:property name="base_width" value="0.125"/>
<xacro:property name="base_length" value="0.38"/>
<xacro:property name="base_height" value="0.06"/>

<xacro:property name="wheel_radius" value="0.033"/>
<xacro:property name="wheel_width" value="0.03"/>
<!-- overall width 0.2 -->
<xacro:property name="wheel_ygap" value="0.0225"/>
<xacro:property name="wheel_zoff" value="0.015"/>
<xacro:property name="wheel_rear_xoff" value="0.145"/>
<xacro:property name="wheel_front_xoff" value="0.115"/>

<xacro:property name="iphone_mount_zoff" value="0.09"/>
<xacro:property name="iphone_mount_xoff" value="0.115"/>

<xacro:property name="iphone_width" value="0.077"/>
<xacro:property name="iphone_thickness" value="0.01"/>
<xacro:property name="iphone_height" value="0.152"/>


<xacro:property name="caster_xoff" value="0.14"/>

<!-- Robot Base -->
<link name="base_link">
    <visual>
        <geometry>
            <box size="${base_length} ${base_width} ${base_height}"/>
        </geometry>
        <material name="Cyan">
            <color rgba="0 1.0 1.0 1.0"/>
        </material>
    </visual>
</link>

<!-- Robot Footprint -->
<link name="base_footprint"/>

<joint name="base_joint" type="fixed">
    <parent link="base_link"/>
    <child link="base_footprint"/>
    <origin xyz="0.0 0.0 ${-(wheel_radius+wheel_zoff)}" rpy="0 0 0"/>
</joint>

<!-- Wheels -->
<xacro:macro name="rear_wheel" params="prefix x_reflect y_reflect">
    <link name="${prefix}_link">
        <visual>
            <origin xyz="0 0 0" rpy="${pi/2} 0 0"/>
            <geometry>
                <cylinder radius="${wheel_radius}" length="${wheel_width}"/>
            </geometry>
            <material name="Gray">
                <color rgba="0.5 0.5 0.5 1.0"/>
            </material>
        </visual>
    </link>

    <joint name="${prefix}_joint" type="continuous">
        <parent link="base_link"/>
        <child link="${prefix}_link"/>
        <origin xyz="${x_reflect*wheel_rear_xoff} ${y_reflect*(base_width/2+wheel_ygap)} ${-wheel_zoff}" rpy="0 0 0"/>
        <axis xyz="0 1 0"/>
    </joint>
</xacro:macro>

<xacro:rear_wheel prefix="drivewhl_rear_l" x_reflect="-1" y_reflect="1" />
<xacro:rear_wheel prefix="drivewhl_rear_r" x_reflect="-1" y_reflect="-1" />

<xacro:macro name="front_wheel" params="prefix x_reflect y_reflect">
    <link name="${prefix}_link">
        <visual>
            <origin xyz="0 0 0" rpy="${pi/2} 0 0"/>
            <geometry>
                <cylinder radius="${wheel_radius}" length="${wheel_width}"/>
            </geometry>
            <material name="Gray">
                <color rgba="0.5 0.5 0.5 1.0"/>
            </material>
        </visual>
    </link>

    <joint name="${prefix}_joint" type="continuous">
        <parent link="base_link"/>
        <child link="${prefix}_link"/>
        <origin xyz="${x_reflect*wheel_front_xoff} ${y_reflect*(base_width/2+wheel_ygap)} ${-wheel_zoff}" rpy="0 0 0"/>
        <axis xyz="0 1 0"/>
    </joint>
</xacro:macro>

<xacro:front_wheel prefix="drivewhl_front_l" x_reflect="1" y_reflect="1" />
<xacro:front_wheel prefix="drivewhl_front_r" x_reflect="1" y_reflect="-1" />

<!-- iPhone Mount Point -->
<link name="iphone_mount_link"/>

<!-- <joint name="iphone_mount_joint" type="fixed">
    <parent link="base_link"/>
    <child link="iphone_mount_link"/>
    <origin xyz="${-(iphone_mount_xoff)} 0.0 ${iphone_mount_zoff}" rpy="0 0 0"/>
</joint> -->

<joint name="iphone_mount_joint" type="fixed">
    <parent link="iphone_mount_link"/>
    <child link="base_link"/>
    <origin xyz="${(iphone_mount_xoff)} 0.0 ${-(iphone_mount_zoff)}" rpy="0 0 0"/>
</joint>

<!-- iPhone -->
<link name="iphone_link">
    <visual>
        <geometry>
            <box size="${iphone_width} ${iphone_height} ${iphone_thickness}"/>
        </geometry>
        <material name="Cyan">
            <color rgba="0 1.0 1.0 1.0"/>
        </material>
    </visual>
</link>

<!-- <joint name="iphone_link_joint" type="fixed">
    <parent link="iphone_mount_link"/>
    <child link="iphone_link"/>
    <origin xyz="${-(iphone_thickness/2)} 0.0 0.0" rpy="1.57 0 -1.57"/>
</joint> -->

<joint name="iphone_link_joint" type="fixed">
    <parent link="iphone_link"/>
    <child link="iphone_mount_link"/>
    <origin xyz="0.0 0.0 ${-(iphone_thickness/2)}" rpy="-1.57 1.57 0"/>
</joint>

<link name="sensors_link"/>

<joint name="sensors_joint" type="fixed">
    <parent link="iphone_link"/>
    <child link="sensors_link"/>
    <origin xyz="0.0 0.0 0.0" rpy="3.14 0 0"/>
</joint>

</robot>